Workbook

Sheet Input_Data
A1: State | B1: Herbicides (kg/1000kg lint) | C1: Insecticides (kg/1000kg lint) | D1: Phosphoric Acid (kg/1000kg lint) | E1: Potassium Oxide (kg/1000kg lint) | F1: Calcium Carbonate (kg/1000kg lint) | G1: N Fertilizer (kg/1000kg lint) | H1: Diesel (L/1000kg lint) | I1: N2O Emission (kg/1000kg lint) | J1: Irrigation Water (m³/1000kg lint)_year 2023 surveyed | K1: Electricity (kWh/1000kg lint) | L1: Irrigation Water (m³/1000kg lint)_year 2049 predicted ssp1 | M1: Irrigation Water (m³/1000kg lint)_year 2049 predicted ssp2 | N1: Irrigation Water (m³/1000kg lint)_year 2049 predicted ssp3 | O1: Irrigation Water (m³/1000kg lint)_year 2049 predicted ssp5 | P1: Natural Gas Low (m3/1000kg) | Q1: Natural Gas High (m3/1000kg) | R1: Electricity Ginning Low (kWh/1000kg) | S1: Electricity Ginning High (kWh/1000kg) | U1: Allocation factor
A2: Alabama | B2: 3.17 | C2: 0.28 | D2: 39.84 | E2: 77.03 | F2: 1.59 | G2: 95.03 | H2: =33.7*$U$2 -> 27.7688 | I2: 3 | J2: 111.78591 | K2: =414.1*$U$2 -> 341.2184 | L2: 617.90209 | M2: 435.05928 | N2: 611.26233 | O2: 616.44432 | P2: 3.4 | Q2: 17.9 | R2: 158.5 | S2: 181.4 | U2: 0.824
A3: Arizona | B3: 1.44 | C3: 0.18 | D3: 10.04 | E3: 1.11 | F3: 0.36 | G3: 101.74 | H3: =95.6*$U$2 -> 78.7744 | I3: 0.9 | J3: 7132.1244 | K3: =1101.1*$U$2 -> 907.3064 | L3: 4911.4717 | M3: 6801.2972 | N3: 5708.2629 | O3: 6722.5369 | P3: 3.4 | Q3: 17.9 | R3: 158.5 | S3: 181.4
A4: Arkansas | B4: 2.52 | C4: 1.2 | D4: 31.98 | E4: 60.66 | F4: 2.16 | G4: 102.31 | H4: =71*$U$2 -> 58.504 | I4: 3.2 | J4: 1435.7417 | K4: =490.4*$U$2 -> 404.0896 | L4: 936.96795 | M4: 932.71956 | N4: 1131.196 | O4: 990.88711 | P4: 3.4 | Q4: 17.9 | R4: 158.5 | S4: 181.4
A5: California | B5: 1.27 | C5: 0.47 | D5: 4.18 | E5: 8.47 | F5: 1.29 | G5: 65.76 | H5: =94.9*$U$2 -> 78.1976 | I5: 0.6 | J5: 5342.918 | K5: =574.3*$U$2 -> 473.2232 | L5: 4027.3915 | M5: 4395.8008 | N5: 4062.4887 | O5: 4402.8162 | P5: 3.4 | Q5: 17.9 | R5: 158.5 | S5: 181.4
A6: Florida | B6: 3.9 | C6: 0.7 | D6: 30.96 | E6: 41.49 | F6: 1.46 | G6: 86.91 | H6: =110.2*$U$2 -> 90.8048 | I6: 2.7 | J6: 344.35488 | K6: =463.1*$U$2 -> 381.5944 | L6: 532.32319 | M6: 514.97338 | N6: 364.75033 | O6: 375.19915 | P6: 3.4 | Q6: 17.9 | R6: 158.5 | S6: 181.4
A7: Georgia | B7: 2.78 | C7: 0.3 | D7: 44.54 | E7: 78.25 | F7: 1.61 | G7: 87.57 | H7: =56.4*$U$2 -> 46.4736 | I7: 2.8 | J7: 446.11614 | K7: =741.2*$U$2 -> 610.7488 | L7: 457.79166 | M7: 204.34856 | N7: 447.4439 | O7: 308.91436 | P7: 3.4 | Q7: 17.9 | R7: 158.5 | S7: 181.4
A8: Kansas | B8: 3.9 | C8: 0.7 | D8: 30.96 | E8: 41.49 | F8: 1.46 | G8: 86.91 | H8: =101.3*$U$2 -> 83.4712 | I8: 0.8 | J8: 480.09456 | K8: =1172.8*$U$2 -> 966.3872 | L8: 709.02083 | M8: 1292.909 | N8: 1285.9128 | O8: 1524.3521 | P8: 3.4 | Q8: 17.9 | R8: 158.5 | S8: 181.4
A9: Louisiana | B9: 3.82 | C9: 1.46 | D9: 34.16 | E9: 55.66 | F9: 1.74 | G9: 70.38 | H9: =82.4*$U$2 -> 67.8976 | I9: 2.2 | J9: 444.19466 | K9: =523.5*$U$2 -> 431.364 | L9: 702.66213 | M9: 647.40363 | N9: 706.94023 | O9: 688.79315 | P9: 3.4 | Q9: 17.9 | R9: 158.5 | S9: 181.4
A10: Mississippi | B10: 3.29 | C10: 1.4 | D10: 19.98 | E10: 57.2 | F10: 1.52 | G10: 87.44 | H10: =77.5*$U$2 -> 63.86 | I10: 2.8 | J10: 463.41946 | K10: =465.7*$U$2 -> 383.7368 | L10: 961.52087 | M10: 884.2239 | N10: 913.3325 | O10: 924.86941 | P10: 3.4 | Q10: 17.9 | R10: 158.5 | S10: 181.4
A11: Missouri | B11: 2.11 | C11: 0.91 | D11: 29.6 | E11: 48.89 | F11: 2.26 | G11: 77.92 | H11: =93.8*$U$2 -> 77.2912 | I11: 2.5 | J11: 651.56859 | K11: =746.2*$U$2 -> 614.8688 | L11: 656.77068 | M11: 677.06836 | N11: 992.13113 | O11: 821.15707 | P11: 3.4 | Q11: 17.9 | R11: 158.5 | S11: 181.4
A12: New Mexico | B12: 3.9 | C12: 0.7 | D12: 30.96 | E12: 41.49 | F12: 1.46 | G12: 86.91 | H12: =199.9*$U$2 -> 164.7176 | I12: 0.8 | J12: 3962.1673 | K12: =2082.1*$U$2 -> 1715.6504 | L12: 3415.0784 | M12: 5630.5468 | N12: 4532.319 | O12: 6276.7756 | P12: 3.4 | Q12: 17.9 | R12: 158.5 | S12: 181.4
A13: North Carolina | B13: 3.3 | C13: 0.57 | D13: 21.92 | E13: 72.02 | F13: 1.48 | G13: 74.65 | H13: =75.5*$U$2 -> 62.212 | I13: 2.4 | J13: 28.744973 | K13: =994.9*$U$2 -> 819.7976 | L13: 467.71058 | M13: 319.65048 | N13: 278.40785 | O13: 107.04586 | P13: 3.4 | Q13: 17.9 | R13: 158.5 | S13: 181.4
A14: Oklahoma | B14: 6.5 | C14: 0.64 | D14: 38.49 | E14: 9.36 | F14: 1.99 | G14: 123.54 | H14: =114.3*$U$2 -> 94.1832 | I14: 1.1 | J14: 1351.2464 | K14: =1214.6*$U$2 -> 1000.8304 | L14: 815.04715 | M14: 1132.4579 | N14: 792.99676 | O14: 1269.6717 | P14: 3.4 | Q14: 17.9 | R14: 158.5 | S14: 181.4
A15: South Carolina | B15: 3.98 | C15: 0.3 | D15: 29.31 | E15: 106.56 | F15: 2.47 | G15: 97.59 | H15: =65.2*$U$2 -> 53.7248 | I15: 3.1 | J15: 194.26796 | K15: =729.8*$U$2 -> 601.3552 | L15: 611.85881 | M15: 301.56042 | N15: 543.94203 | O15: 308.61104 | P15: 3.4 | Q15: 17.9 | R15: 158.5 | S15: 181.4
A16: Tennessee | B16: 3.05 | C16: 0.69 | D16: 37.85 | E16: 68.56 | F16: 1.4 | G16: 72.66 | H16: =26.1*$U$2 -> 21.5064 | I16: 2.3 | J16: 101.9439 | K16: =423.7*$U$2 -> 349.1288 | L16: 520.84755 | M16: 572.48404 | N16: 511.60373 | O16: 467.95313 | P16: 3.4 | Q16: 17.9 | R16: 158.5 | S16: 181.4
A17: Texas | B17: 5.7 | C17: 0.65 | D17: 30.67 | E17: 4.79 | F17: 1.01 | G17: 85.68 | H17: =189.2*$U$2 -> 155.9008 | I17: 0.7 | J17: 2998.2513 | K17: =1191.7*$U$2 -> 981.9608 | L17: 828.81903 | M17: 1815.1219 | N17: 643.15604 | O17: 2366.1579 | P17: 3.4 | Q17: 17.9 | R17: 158.5 | S17: 181.4
A18: Virginia | B18: 3.9 | C18: 0.7 | D18: 30.96 | E18: 41.49 | F18: 1.46 | G18: 86.91 | H18: =48.7*$U$2 -> 40.1288 | I18: 2.7 | J18: 1.7033495 | K18: =677.9*$U$2 -> 558.5896 | L18: 198.67893 | M18: 289.62433 | N18: 83.498432 | O18: 15.681026 | P18: 3.4 | Q18: 17.9 | R18: 158.5 | S18: 181.4

Sheet Input_Data_Electrified
A1: State | B1: Herbicides (kg/1000kg lint) | C1: Insecticides (kg/1000kg lint) | D1: Phosphoric Acid (kg/1000kg lint) | E1: Potassium Oxide (kg/1000kg lint) | F1: Calcium Carbonate (kg/1000kg lint) | G1: N Fertilizer (kg/1000kg lint) | H1: Diesel (L/1000kg lint) | I1: N2O Emission (kg/1000kg lint) | J1: Irrigation Water (m³/1000kg lint)_year 2023 surveyed | K1: Electricity (kWh/1000kg lint) | L1: Irrigation Water (m³/1000kg lint)_year 2049 predicted ssp1 | M1: Irrigation Water (m³/1000kg lint)_year 2049 predicted ssp2 | N1: Irrigation Water (m³/1000kg lint)_year 2049 predicted ssp3 | O1: Irrigation Water (m³/1000kg lint)_year 2049 predicted ssp5 | P1: Natural Gas Low (m3/1000kg) | Q1: Natural Gas High (m3/1000kg) | R1: Electricity Ginning Low (kWh/1000kg) | S1: Electricity Ginning High (kWh/1000kg) | U1: Conversion assumption | V1: Value
A2: =Input_Data!A2 -> Alabama | B2: =Input_Data!B2 -> 3.17 | C2: =Input_Data!C2 -> 0.28 | D2: =Input_Data!D2 -> 39.84 | E2: =Input_Data!E2 -> 77.03 | F2: =Input_Data!F2 -> 1.59 | G2: =Input_Data!G2 -> 95.03 | H2: =0 -> 0 | I2: =Input_Data!I2 -> 3 | J2: =Input_Data!J2 -> 111.78591 | K2: =Input_Data!K2+Input_Data!H2*$V$2 -> 463.40112 | L2: =Input_Data!L2 -> 617.90209 | M2: =Input_Data!M2 -> 435.05928 | N2: =Input_Data!N2 -> 611.26233 | O2: =Input_Data!O2 -> 616.44432 | P2: =0 -> 0 | Q2: =0 -> 0 | R2: =Input_Data!R2+Input_Data!P2*$V$3 -> 194.2 | S2: =Input_Data!S2+Input_Data!Q2*$V$3 -> 369.35 | U2: Electricity replacing diesel (kWh/L) | V2: 4.4
A3: =Input_Data!A3 -> Arizona | B3: =Input_Data!B3 -> 1.44 | C3: =Input_Data!C3 -> 0.18 | D3: =Input_Data!D3 -> 10.04 | E3: =Input_Data!E3 -> 1.11 | F3: =Input_Data!F3 -> 0.36 | G3: =Input_Data!G3 -> 101.74 | H3: =0 -> 0 | I3: =Input_Data!I3 -> 0.9 | J3: =Input_Data!J3 -> 7132.1244 | K3: =Input_Data!K3+Input_Data!H3*$V$2 -> 1253.9138 | L3: =Input_Data!L3 -> 4911.4717 | M3: =Input_Data!M3 -> 6801.2972 | N3: =Input_Data!N3 -> 5708.2629 | O3: =Input_Data!O3 -> 6722.5369 | P3: =0 -> 0 | Q3: =0 -> 0 | R3: =Input_Data!R3+Input_Data!P3*$V$3 -> 194.2 | S3: =Input_Data!S3+Input_Data!Q3*$V$3 -> 369.35 | U3: Electricity replacing ginning NG (kWh/m³) | V3: 10.5 | W3: Back-calculated from original sheet: 158.5+3.4×10.5=194.2; 181.4+17.9×10.5=369.35
A4: =Input_Data!A4 -> Arkansas | B4: =Input_Data!B4 -> 2.52 | C4: =Input_Data!C4 -> 1.2 | D4: =Input_Data!D4 -> 31.98 | E4: =Input_Data!E4 -> 60.66 | F4: =Input_Data!F4 -> 2.16 | G4: =Input_Data!G4 -> 102.31 | H4: =0 -> 0 | I4: =Input_Data!I4 -> 3.2 | J4: =Input_Data!J4 -> 1435.7417 | K4: =Input_Data!K4+Input_Data!H4*$V$2 -> 661.5072 | L4: =Input_Data!L4 -> 936.96795 | M4: =Input_Data!M4 -> 932.71956 | N4: =Input_Data!N4 -> 1131.196 | O4: =Input_Data!O4 -> 990.88711 | P4: =0 -> 0 | Q4: =0 -> 0 | R4: =Input_Data!R4+Input_Data!P4*$V$3 -> 194.2 | S4: =Input_Data!S4+Input_Data!Q4*$V$3 -> 369.35
A5: =Input_Data!A5 -> California | B5: =Input_Data!B5 -> 1.27 | C5: =Input_Data!C5 -> 0.47 | D5: =Input_Data!D5 -> 4.18 | E5: =Input_Data!E5 -> 8.47 | F5: =Input_Data!F5 -> 1.29 | G5: =Input_Data!G5 -> 65.76 | H5: =0 -> 0 | I5: =Input_Data!I5 -> 0.6 | J5: =Input_Data!J5 -> 5342.918 | K5: =Input_Data!K5+Input_Data!H5*$V$2 -> 817.29264 | L5: =Input_Data!L5 -> 4027.3915 | M5: =Input_Data!M5 -> 4395.8008 | N5: =Input_Data!N5 -> 4062.4887 | O5: =Input_Data!O5 -> 4402.8162 | P5: =0 -> 0 | Q5: =0 -> 0 | R5: =Input_Data!R5+Input_Data!P5*$V$3 -> 194.2 | S5: =Input_Data!S5+Input_Data!Q5*$V$3 -> 369.35
A6: =Input_Data!A6 -> Florida | B6: =Input_Data!B6 -> 3.9 | C6: =Input_Data!C6 -> 0.7 | D6: =Input_Data!D6 -> 30.96 | E6: =Input_Data!E6 -> 41.49 | F6: =Input_Data!F6 -> 1.46 | G6: =Input_Data!G6 -> 86.91 | H6: =0 -> 0 | I6: =Input_Data!I6 -> 2.7 | J6: =Input_Data!J6 -> 344.35488 | K6: =Input_Data!K6+Input_Data!H6*$V$2 -> 781.13552 | L6: =Input_Data!L6 -> 532.32319 | M6: =Input_Data!M6 -> 514.97338 | N6: =Input_Data!N6 -> 364.75033 | O6: =Input_Data!O6 -> 375.19915 | P6: =0 -> 0 | Q6: =0 -> 0 | R6: =Input_Data!R6+Input_Data!P6*$V$3 -> 194.2 | S6: =Input_Data!S6+Input_Data!Q6*$V$3 -> 369.35
A7: =Input_Data!A7 -> Georgia | B7: =Input_Data!B7 -> 2.78 | C7: =Input_Data!C7 -> 0.3 | D7: =Input_Data!D7 -> 44.54 | E7: =Input_Data!E7 -> 78.25 | F7: =Input_Data!F7 -> 1.61 | G7: =Input_Data!G7 -> 87.57 | H7: =0 -> 0 | I7: =Input_Data!I7 -> 2.8 | J7: =Input_Data!J7 -> 446.11614 | K7: =Input_Data!K7+Input_Data!H7*$V$2 -> 815.23264 | L7: =Input_Data!L7 -> 457.79166 | M7: =Input_Data!M7 -> 204.34856 | N7: =Input_Data!N7 -> 447.4439 | O7: =Input_Data!O7 -> 308.91436 | P7: =0 -> 0 | Q7: =0 -> 0 | R7: =Input_Data!R7+Input_Data!P7*$V$3 -> 194.2 | S7: =Input_Data!S7+Input_Data!Q7*$V$3 -> 369.35
A8: =Input_Data!A8 -> Kansas | B8: =Input_Data!B8 -> 3.9 | C8: =Input_Data!C8 -> 0.7 | D8: =Input_Data!D8 -> 30.96 | E8: =Input_Data!E8 -> 41.49 | F8: =Input_Data!F8 -> 1.46 | G8: =Input_Data!G8 -> 86.91 | H8: =0 -> 0 | I8: =Input_Data!I8 -> 0.8 | J8: =Input_Data!J8 -> 480.09456 | K8: =Input_Data!K8+Input_Data!H8*$V$2 -> 1333.6605 | L8: =Input_Data!L8 -> 709.02083 | M8: =Input_Data!M8 -> 1292.909 | N8: =Input_Data!N8 -> 1285.9128 | O8: =Input_Data!O8 -> 1524.3521 | P8: =0 -> 0 | Q8: =0 -> 0 | R8: =Input_Data!R8+Input_Data!P8*$V$3 -> 194.2 | S8: =Input_Data!S8+Input_Data!Q8*$V$3 -> 369.35
A9: =Input_Data!A9 -> Louisiana | B9: =Input_Data!B9 -> 3.82 | C9: =Input_Data!C9 -> 1.46 | D9: =Input_Data!D9 -> 34.16 | E9: =Input_Data!E9 -> 55.66 | F9: =Input_Data!F9 -> 1.74 | G9: =Input_Data!G9 -> 70.38 | H9: =0 -> 0 | I9: =Input_Data!I9 -> 2.2 | J9: =Input_Data!J9 -> 444.19466 | K9: =Input_Data!K9+Input_Data!H9*$V$2 -> 730.11344 | L9: =Input_Data!L9 -> 702.66213 | M9: =Input_Data!M9 -> 647.40363 | N9: =Input_Data!N9 -> 706.94023 | O9: =Input_Data!O9 -> 688.79315 | P9: =0 -> 0 | Q9: =0 -> 0 | R9: =Input_Data!R9+Input_Data!P9*$V$3 -> 194.2 | S9: =Input_Data!S9+Input_Data!Q9*$V$3 -> 369.35
A10: =Input_Data!A10 -> Mississippi | B10: =Input_Data!B10 -> 3.29 | C10: =Input_Data!C10 -> 1.4 | D10: =Input_Data!D10 -> 19.98 | E10: =Input_Data!E10 -> 57.2 | F10: =Input_Data!F10 -> 1.52 | G10: =Input_Data!G10 -> 87.44 | H10: =0 -> 0 | I10: =Input_Data!I10 -> 2.8 | J10: =Input_Data!J10 -> 463.41946 | K10: =Input_Data!K10+Input_Data!H10*$V$2 -> 664.7208 | L10: =Input_Data!L10 -> 961.52087 | M10: =Input_Data!M10 -> 884.2239 | N10: =Input_Data!N10 -> 913.3325 | O10: =Input_Data!O10 -> 924.86941 | P10: =0 -> 0 | Q10: =0 -> 0 | R10: =Input_Data!R10+Input_Data!P10*$V$3 -> 194.2 | S10: =Input_Data!S10+Input_Data!Q10*$V$3 -> 369.35
A11: =Input_Data!A11 -> Missouri | B11: =Input_Data!B11 -> 2.11 | C11: =Input_Data!C11 -> 0.91 | D11: =Input_Data!D11 -> 29.6 | E11: =Input_Data!E11 -> 48.89 | F11: =Input_Data!F11 -> 2.26 | G11: =Input_Data!G11 -> 77.92 | H11: =0 -> 0 | I11: =Input_Data!I11 -> 2.5 | J11: =Input_Data!J11 -> 651.56859 | K11: =Input_Data!K11+Input_Data!H11*$V$2 -> 954.95008 | L11: =Input_Data!L11 -> 656.77068 | M11: =Input_Data!M11 -> 677.06836 | N11: =Input_Data!N11 -> 992.13113 | O11: =Input_Data!O11 -> 821.15707 | P11: =0 -> 0 | Q11: =0 -> 0 | R11: =Input_Data!R11+Input_Data!P11*$V$3 -> 194.2 | S11: =Input_Data!S11+Input_Data!Q11*$V$3 -> 369.35
A12: =Input_Data!A12 -> New Mexico | B12: =Input_Data!B12 -> 3.9 | C12: =Input_Data!C12 -> 0.7 | D12: =Input_Data!D12 -> 30.96 | E12: =Input_Data!E12 -> 41.49 | F12: =Input_Data!F12 -> 1.46 | G12: =Input_Data!G12 -> 86.91 | H12: =0 -> 0 | I12: =Input_Data!I12 -> 0.8 | J12: =Input_Data!J12 -> 3962.1673 | K12: =Input_Data!K12+Input_Data!H12*$V$2 -> 2440.4078 | L12: =Input_Data!L12 -> 3415.0784 | M12: =Input_Data!M12 -> 5630.5468 | N12: =Input_Data!N12 -> 4532.319 | O12: =Input_Data!O12 -> 6276.7756 | P12: =0 -> 0 | Q12: =0 -> 0 | R12: =Input_Data!R12+Input_Data!P12*$V$3 -> 194.2 | S12: =Input_Data!S12+Input_Data!Q12*$V$3 -> 369.35
A13: =Input_Data!A13 -> North Carolina | B13: =Input_Data!B13 -> 3.3 | C13: =Input_Data!C13 -> 0.57 | D13: =Input_Data!D13 -> 21.92 | E13: =Input_Data!E13 -> 72.02 | F13: =Input_Data!F13 -> 1.48 | G13: =Input_Data!G13 -> 74.65 | H13: =0 -> 0 | I13: =Input_Data!I13 -> 2.4 | J13: =Input_Data!J13 -> 28.744973 | K13: =Input_Data!K13+Input_Data!H13*$V$2 -> 1093.5304 | L13: =Input_Data!L13 -> 467.71058 | M13: =Input_Data!M13 -> 319.65048 | N13: =Input_Data!N13 -> 278.40785 | O13: =Input_Data!O13 -> 107.04586 | P13: =0 -> 0 | Q13: =0 -> 0 | R13: =Input_Data!R13+Input_Data!P13*$V$3 -> 194.2 | S13: =Input_Data!S13+Input_Data!Q13*$V$3 -> 369.35
A14: =Input_Data!A14 -> Oklahoma | B14: =Input_Data!B14 -> 6.5 | C14: =Input_Data!C14 -> 0.64 | D14: =Input_Data!D14 -> 38.49 | E14: =Input_Data!E14 -> 9.36 | F14: =Input_Data!F14 -> 1.99 | G14: =Input_Data!G14 -> 123.54 | H14: =0 -> 0 | I14: =Input_Data!I14 -> 1.1 | J14: =Input_Data!J14 -> 1351.2464 | K14: =Input_Data!K14+Input_Data!H14*$V$2 -> 1415.2365 | L14: =Input_Data!L14 -> 815.04715 | M14: =Input_Data!M14 -> 1132.4579 | N14: =Input_Data!N14 -> 792.99676 | O14: =Input_Data!O14 -> 1269.6717 | P14: =0 -> 0 | Q14: =0 -> 0 | R14: =Input_Data!R14+Input_Data!P14*$V$3 -> 194.2 | S14: =Input_Data!S14+Input_Data!Q14*$V$3 -> 369.35
A15: =Input_Data!A15 -> South Carolina | B15: =Input_Data!B15 -> 3.98 | C15: =Input_Data!C15 -> 0.3 | D15: =Input_Data!D15 -> 29.31 | E15: =Input_Data!E15 -> 106.56 | F15: =Input_Data!F15 -> 2.47 | G15: =Input_Data!G15 -> 97.59 | H15: =0 -> 0 | I15: =Input_Data!I15 -> 3.1 | J15: =Input_Data!J15 -> 194.26796 | K15: =Input_Data!K15+Input_Data!H15*$V$2 -> 837.74432 | L15: =Input_Data!L15 -> 611.85881 | M15: =Input_Data!M15 -> 301.56042 | N15: =Input_Data!N15 -> 543.94203 | O15: =Input_Data!O15 -> 308.61104 | P15: =0 -> 0 | Q15: =0 -> 0 | R15: =Input_Data!R15+Input_Data!P15*$V$3 -> 194.2 | S15: =Input_Data!S15+Input_Data!Q15*$V$3 -> 369.35
... A18: =Input_Data!A18 -> Virginia | B18: =Input_Data!B18 -> 3.9 | C18: =Input_Data!C18 -> 0.7 | D18: =Input_Data!D18 -> 30.96 | E18: =Input_Data!E18 -> 41.49 | F18: =Input_Data!F18 -> 1.46 | G18: =Input_Data!G18 -> 86.91 | H18: =0 -> 0 | I18: =Input_Data!I18 -> 2.7 | J18: =Input_Data!J18 -> 1.7033495 | K18: =Input_Data!K18+Input_Data!H18*$V$2 -> 735.15632 | L18: =Input_Data!L18 -> 198.67893 | M18: =Input_Data!M18 -> 289.62433 | N18: =Input_Data!N18 -> 83.498432 | O18: =Input_Data!O18 -> 15.681026 | P18: =0 -> 0 | Q18: =0 -> 0 | R18: =Input_Data!R18+Input_Data!P18*$V$3 -> 194.2 | S18: =Input_Data!S18+Input_Data!Q18*$V$3 -> 369.35

Sheet Impact_Factors
A1: Component | B1: Unit | C1: GHG (kg CO2-eq/unit) | D1: Energy Use (MJ/unit) | E1: Water Use (L/unit) | F1: Data Source
A2: Herbicides | B2: kg | C2: 24.51 | D2: 395 | E2: 67.74 | F2: GREET, MIX: FOR CORN STOVER
A3: Insecticides | B3: kg | C3: 20.9 | D3: 307 | E3: 38.91 | F3: GREET, INSECTICIDES PATHWAY
A4: Phosphoric Acid | B4: kg | C4: 1.15 | D4: 17 | E4: 36.81 | F4: GREET, PHOSPHORIC ACID
A5: Potassium Oxide | B5: kg | C5: 0.31 | D5: 7.13 | E5: 9.89 | F5: GREET, POTASSIUM OXIDE PRODUCTION IN BRAZIL
A6: Calcium Carbonate | B6: kg | C6: =9.49/1000 -> 0.00949 | D6: 0.12 | E6: 0.11 | F6: GREET, CACO3 AS FERTILIZER PRODUCTS
A7: N Fertilizer Production | B7: kg N | C7: 3.5 | D7: 55 | E7: 15.35 | F7: GREET, NITROGEN AVERAGE
A8: Diesel | B8: L | C8: 3.21 | D8: 42 | E8: 3 | F8: GREET, DIESEL FOR NON ROAD
A9: N2O Emission | B9: kg N2O | C9: 273 | D9: 0 | E9: 0 | F9: IPCC
A10: Irrigation Water | B10: m³ | C10: 0 | D10: 0 | E10: 1000 | F10: GREET, PRIMARY RESOURCE
A11: Natural Gas (ginning) | B11: m³ | C11: 0.3478 | D11: 38 | E11: 0.4148 | F11: GREET

Sheet State_Electricity_Factors
A1: State | B1: GHG Factor (kg CO2-eq/kWh) | C1: Energy Factor (MJ/kWh) | D1: Water Factor (L/kWh)
A2: Alabama | B2: 0.43 | C2: 7.3886633 | D2: 2.4453655
A3: Arizona | B3: 0.48 | C3: 7.4259281 | D3: 2.4503765
A4: Arkansas | B4: 0.6 | C4: 8.376445 | D4: 2.2429615
A5: California | B5: 0.25 | C5: 6.3351809 | D5: 4.4799563
A6: Florida | B6: 0.53 | C6: 8.5650474 | D6: 1.0749028
A7: Georgia | B7: 0.49 | C7: 7.841309 | D7: 1.6088865
A8: Kansas | B8: 0.47 | C8: 7.156586 | D8: 1.0929321
A9: Louisiana | B9: 0.58 | C9: 9.2084258 | D9: 1.3152639
A10: Mississippi | B10: 0.5 | C10: 8.3881492 | D10: 0.98288341
A11: Missouri | B11: 0.9 | C11: 9.867809 | D11: 1.9105423
A12: New Mexico | B12: 0.79 | C12: 9.620501 | D12: 1.3178857
A13: North Carolina | B13: 0.44 | C13: 7.2730207 | D13: 1.8462385
... A18: Virginia | B18: 0.39 | C18: 7.4165169 | D18: 1.4399712

Sheet Scenario_Definitions
A1: Scenario Name | B1: Description | C1: Other Changes
A2: Baseline | B2: Current practices | C2: None
A3: Pro Electricity | B3: Pro electricity: use 4.4 kwh electricity to replace 1 liter diesel | C3: None

Sheet Results_GHG_Breakdown
A1: State | B1: Herbicides (kg CO2/1000kg lint) | C1: Insecticides (kg CO2/1000kg lint) | D1: Phosphoric Acid (kg CO2/1000kg lint) | E1: Potassium Oxide (kg CO2/1000kg lint) | F1: Calcium Carbonate (kg CO2/1000kg lint) | G1: N Fertilizer (kg CO2/1000kg lint) | H1: Diesel (kg CO2/1000kg lint) | I1: N2O Emission (kg CO2/1000kg lint) | J1: Irrigation Water (kg CO2/1000kg lint)_year 2023 surveyed | K1: Electricity (kg CO2 /1000 kg cotton lint) | L1: NG Ginning Low (kg CO2/1000kg lint) | M1: NG Ginning High (kg CO2/1000kg lint) | N1: Electricity Ginning Low (kg CO2/1000kg lint) | O1: Electricity Ginning High (kg CO2/1000kg lint)
A2: Alabama | B2: {=Input_Data!$B2:$J2*TRANSPOSE(Impact_Factors!$C$2:$C$10)} -> 77.6967 | C2: 5.852 | D2: 45.816 | E2: 23.8793 | F2: 0.0150891 | G2: 332.605 | H2: 89.137848 | I2: 819 | J2: 0 | K2: =Input_Data!K2*State_Electricity_Factors!B2 -> 146.72391 | L2: =Input_Data!P2*Impact_Factors!$C$11 -> 1.18252 | M2: =Input_Data!Q2*Impact_Factors!$C$11 -> 6.22562 | N2: =Input_Data!R2*State_Electricity_Factors!B2 -> 68.155 | O2: =Input_Data!S2*State_Electricity_Factors!B2 -> 78.002
A3: Arizona | B3: {=Input_Data!$B3:$J3*TRANSPOSE(Impact_Factors!$C$2:$C$10)} -> 35.2944 | C3: 3.762 | D3: 11.546 | E3: 0.3441 | F3: 0.0034164 | G3: 356.09 | H3: 252.86582 | I3: 245.7 | J3: 0 | K3: =Input_Data!K3*State_Electricity_Factors!B3 -> 435.50707 | L3: =Input_Data!P3*Impact_Factors!$C$11 -> 1.18252 | M3: =Input_Data!Q3*Impact_Factors!$C$11 -> 6.22562 | N3: =Input_Data!R3*State_Electricity_Factors!B3 -> 76.08 | O3: =Input_Data!S3*State_Electricity_Factors!B3 -> 87.072
A4: Arkansas | B4: {=Input_Data!$B4:$J4*TRANSPOSE(Impact_Factors!$C$2:$C$10)} -> 61.7652 | C4: 25.08 | D4: 36.777 | E4: 18.8046 | F4: 0.0204984 | G4: 358.085 | H4: 187.79784 | I4: 873.6 | J4: 0 | K4: =Input_Data!K4*State_Electricity_Factors!B4 -> 242.45376 | L4: =Input_Data!P4*Impact_Factors!$C$11 -> 1.18252 | M4: =Input_Data!Q4*Impact_Factors!$C$11 -> 6.22562 | N4: =Input_Data!R4*State_Electricity_Factors!B4 -> 95.1 | O4: =Input_Data!S4*State_Electricity_Factors!B4 -> 108.84
A5: California | B5: {=Input_Data!$B5:$J5*TRANSPOSE(Impact_Factors!$C$2:$C$10)} -> 31.1277 | C5: 9.823 | D5: 4.807 | E5: 2.6257 | F5: 0.0122421 | G5: 230.16 | H5: 251.0143 | I5: 163.8 | J5: 0 | K5: =Input_Data!K5*State_Electricity_Factors!B5 -> 118.3058 | L5: =Input_Data!P5*Impact_Factors!$C$11 -> 1.18252 | M5: =Input_Data!Q5*Impact_Factors!$C$11 -> 6.22562 | N5: =Input_Data!R5*State_Electricity_Factors!B5 -> 39.625 | O5: =Input_Data!S5*State_Electricity_Factors!B5 -> 45.35
A6: Florida | B6: {=Input_Data!$B6:$J6*TRANSPOSE(Impact_Factors!$C$2:$C$10)} -> 95.589 | C6: 14.63 | D6: 35.604 | E6: 12.8619 | F6: 0.0138554 | G6: 304.185 | H6: 291.48341 | I6: 737.1 | J6: 0 | K6: =Input_Data!K6*State_Electricity_Factors!B6 -> 202.24503 | L6: =Input_Data!P6*Impact_Factors!$C$11 -> 1.18252 | M6: =Input_Data!Q6*Impact_Factors!$C$11 -> 6.22562 | N6: =Input_Data!R6*State_Electricity_Factors!B6 -> 84.005 | O6: =Input_Data!S6*State_Electricity_Factors!B6 -> 96.142
A7: Georgia | B7: {=Input_Data!$B7:$J7*TRANSPOSE(Impact_Factors!$C$2:$C$10)} -> 68.1378 | C7: 6.27 | D7: 51.221 | E7: 24.2575 | F7: 0.0152789 | G7: 306.495 | H7: 149.18026 | I7: 764.4 | J7: 0 | K7: =Input_Data!K7*State_Electricity_Factors!B7 -> 299.26691 | L7: =Input_Data!P7*Impact_Factors!$C$11 -> 1.18252 | M7: =Input_Data!Q7*Impact_Factors!$C$11 -> 6.22562 | N7: =Input_Data!R7*State_Electricity_Factors!B7 -> 77.665 | O7: =Input_Data!S7*State_Electricity_Factors!B7 -> 88.886
A8: Kansas | B8: {=Input_Data!$B8:$J8*TRANSPOSE(Impact_Factors!$C$2:$C$10)} -> 95.589 | C8: 14.63 | D8: 35.604 | E8: 12.8619 | F8: 0.0138554 | G8: 304.185 | H8: 267.94255 | I8: 218.4 | J8: 0 | K8: =Input_Data!K8*State_Electricity_Factors!B8 -> 454.20198 | L8: =Input_Data!P8*Impact_Factors!$C$11 -> 1.18252 | M8: =Input_Data!Q8*Impact_Factors!$C$11 -> 6.22562 | N8: =Input_Data!R8*State_Electricity_Factors!B8 -> 74.495 | O8: =Input_Data!S8*State_Electricity_Factors!B8 -> 85.258
A9: Louisiana | B9: {=Input_Data!$B9:$J9*TRANSPOSE(Impact_Factors!$C$2:$C$10)} -> 93.6282 | C9: 30.514 | D9: 39.284 | E9: 17.2546 | F9: 0.0165126 | G9: 246.33 | H9: 217.9513 | I9: 600.6 | J9: 0 | K9: =Input_Data!K9*State_Electricity_Factors!B9 -> 250.19112 | L9: =Input_Data!P9*Impact_Factors!$C$11 -> 1.18252 | M9: =Input_Data!Q9*Impact_Factors!$C$11 -> 6.22562 | N9: =Input_Data!R9*State_Electricity_Factors!B9 -> 91.93 | O9: =Input_Data!S9*State_Electricity_Factors!B9 -> 105.212
A10: Mississippi | B10: {=Input_Data!$B10:$J10*TRANSPOSE(Impact_Factors!$C$2:$C$10)} -> 80.6379 | C10: 29.26 | D10: 22.977 | E10: 17.732 | F10: 0.0144248 | G10: 306.04 | H10: 204.9906 | I10: 764.4 | J10: 0 | K10: =Input_Data!K10*State_Electricity_Factors!B10 -> 191.8684 | L10: =Input_Data!P10*Impact_Factors!$C$11 -> 1.18252 | M10: =Input_Data!Q10*Impact_Factors!$C$11 -> 6.22562 | N10: =Input_Data!R10*State_Electricity_Factors!B10 -> 79.25 | O10: =Input_Data!S10*State_Electricity_Factors!B10 -> 90.7
A11: Missouri | B11: {=Input_Data!$B11:$J11*TRANSPOSE(Impact_Factors!$C$2:$C$10)} -> 51.7161 | C11: 19.019 | D11: 34.04 | E11: 15.1559 | F11: 0.0214474 | G11: 272.72 | H11: 248.10475 | I11: 682.5 | J11: 0 | K11: =Input_Data!K11*State_Electricity_Factors!B11 -> 553.38192 | L11: =Input_Data!P11*Impact_Factors!$C$11 -> 1.18252 | M11: =Input_Data!Q11*Impact_Factors!$C$11 -> 6.22562 | N11: =Input_Data!R11*State_Electricity_Factors!B11 -> 142.65 | O11: =Input_Data!S11*State_Electricity_Factors!B11 -> 163.26
A12: New Mexico | B12: {=Input_Data!$B12:$J12*TRANSPOSE(Impact_Factors!$C$2:$C$10)} -> 95.589 | C12: 14.63 | D12: 35.604 | E12: 12.8619 | F12: 0.0138554 | G12: 304.185 | H12: 528.7435 | I12: 218.4 | J12: 0 | K12: =Input_Data!K12*State_Electricity_Factors!B12 -> 1355.3638 | L12: =Input_Data!P12*Impact_Factors!$C$11 -> 1.18252 | M12: =Input_Data!Q12*Impact_Factors!$C$11 -> 6.22562 | N12: =Input_Data!R12*State_Electricity_Factors!B12 -> 125.215 | O12: =Input_Data!S12*State_Electricity_Factors!B12 -> 143.306
A13: North Carolina | B13: {=Input_Data!$B13:$J13*TRANSPOSE(Impact_Factors!$C$2:$C$10)} -> 80.883 | C13: 11.913 | D13: 25.208 | E13: 22.3262 | F13: 0.0140452 | G13: 261.275 | H13: 199.70052 | I13: 655.2 | J13: 0 | K13: =Input_Data!K13*State_Electricity_Factors!B13 -> 360.71094 | L13: =Input_Data!P13*Impact_Factors!$C$11 -> 1.18252 | M13: =Input_Data!Q13*Impact_Factors!$C$11 -> 6.22562 | N13: =Input_Data!R13*State_Electricity_Factors!B13 -> 69.74 | O13: =Input_Data!S13*State_Electricity_Factors!B13 -> 79.816
... A18: Virginia | B18: {=Input_Data!$B18:$J18*TRANSPOSE(Impact_Factors!$C$2:$C$10)} -> 95.589 | C18: 14.63 | D18: 35.604 | E18: 12.8619 | F18: 0.0138554 | G18: 304.185 | H18: 128.81345 | I18: 737.1 | J18: 0 | K18: =Input_Data!K18*State_Electricity_Factors!B18 -> 217.84994 | L18: =Input_Data!P18*Impact_Factors!$C$11 -> 1.18252 | M18: =Input_Data!Q18*Impact_Factors!$C$11 -> 6.22562 | N18: =Input_Data!R18*State_Electricity_Factors!B18 -> 61.815 | O18: =Input_Data!S18*State_Electricity_Factors!B18 -> 70.746
A20: pro-electricity
A21: State | B21: Herbicides (kg CO2/1000kg lint) | C21: Insecticides (kg CO2/1000kg lint) | D21: Phosphoric Acid (kg CO2/1000kg lint) | E21: Potassium Oxide (kg CO2/1000kg lint) | F21: Calcium Carbonate (kg CO2/1000kg lint) | G21: N Fertilizer (kg CO2/1000kg lint) | H21: Diesel (kg CO2/1000kg lint) | I21: N2O Emission (kg CO2/1000kg lint) | J21: Irrigation Water (kg CO2/1000kg lint)_year 2023 surveyed | K21: Electricity (kg CO2 /1000 kg cotton lint) | L21: NG Ginning Low (kg CO2/1000kg lint) | M21: NG Ginning High (kg CO2/1000kg lint) | N21: Electricity Ginning Low (kg CO2/1000kg lint) | O21: Electricity Ginning High (kg CO2/1000kg lint)
A22: Alabama | B22: {=Input_Data_Electrified!$B2:$J2*TRANSPOSE(Impact_Factors!$C$2:$C$10)} -> 77.6967 | C22: 5.852 | D22: 45.816 | E22: 23.8793 | F22: 0.0150891 | G22: 332.605 | H22: 0 | I22: 819 | J22: 0 | K22: =Input_Data_Electrified!K2*State_Electricity_Factors!B2 -> 199.26248 | L22: =Input_Data_Electrified!P2*Impact_Factors!$C$11 -> 0 | M22: =Input_Data_Electrified!Q2*Impact_Factors!$C$11 -> 0 | N22: =Input_Data_Electrified!R2*State_Electricity_Factors!B2 -> 83.506 | O22: =Input_Data_Electrified!S2*State_Electricity_Factors!B2 -> 158.8205
A23: Arizona | B23: {=Input_Data_Electrified!$B3:$J3*TRANSPOSE(Impact_Factors!$C$2:$C$10)} -> 35.2944 | C23: 3.762 | D23: 11.546 | E23: 0.3441 | F23: 0.0034164 | G23: 356.09 | H23: 0 | I23: 245.7 | J23: 0 | K23: =Input_Data_Electrified!K3*State_Electricity_Factors!B3 -> 601.8786 | L23: =Input_Data_Electrified!P3*Impact_Factors!$C$11 -> 0 | M23: =Input_Data_Electrified!Q3*Impact_Factors!$C$11 -> 0 | N23: =Input_Data_Electrified!R3*State_Electricity_Factors!B3 -> 93.216 | O23: =Input_Data_Electrified!S3*State_Electricity_Factors!B3 -> 177.288
A24: Arkansas | B24: {=Input_Data_Electrified!$B4:$J4*TRANSPOSE(Impact_Factors!$C$2:$C$10)} -> 61.7652 | C24: 25.08 | D24: 36.777 | E24: 18.8046 | F24: 0.0204984 | G24: 358.085 | H24: 0 | I24: 873.6 | J24: 0 | K24: =Input_Data_Electrified!K4*State_Electricity_Factors!B4 -> 396.90432 | L24: =Input_Data_Electrified!P4*Impact_Factors!$C$11 -> 0 | M24: =Input_Data_Electrified!Q4*Impact_Factors!$C$11 -> 0 | N24: =Input_Data_Electrified!R4*State_Electricity_Factors!B4 -> 116.52 | O24: =Input_Data_Electrified!S4*State_Electricity_Factors!B4 -> 221.61
A25: California | B25: {=Input_Data_Electrified!$B5:$J5*TRANSPOSE(Impact_Factors!$C$2:$C$10)} -> 31.1277 | C25: 9.823 | D25: 4.807 | E25: 2.6257 | F25: 0.0122421 | G25: 230.16 | H25: 0 | I25: 163.8 | J25: 0 | K25: =Input_Data_Electrified!K5*State_Electricity_Factors!B5 -> 204.32316 | L25: =Input_Data_Electrified!P5*Impact_Factors!$C$11 -> 0 | M25: =Input_Data_Electrified!Q5*Impact_Factors!$C$11 -> 0 | N25: =Input_Data_Electrified!R5*State_Electricity_Factors!B5 -> 48.55 | O25: =Input_Data_Electrified!S5*State_Electricity_Factors!B5 -> 92.3375
A26: Florida | B26: {=Input_Data_Electrified!$B6:$J6*TRANSPOSE(Impact_Factors!$C$2:$C$10)} -> 95.589 | C26: 14.63 | D26: 35.604 | E26: 12.8619 | F26: 0.0138554 | G26: 304.185 | H26: 0 | I26: 737.1 | J26: 0 | K26: =Input_Data_Electrified!K6*State_Electricity_Factors!B6 -> 414.00183 | L26: =Input_Data_Electrified!P6*Impact_Factors!$C$11 -> 0 | M26: =Input_Data_Electrified!Q6*Impact_Factors!$C$11 -> 0 | N26: =Input_Data_Electrified!R6*State_Electricity_Factors!B6 -> 102.926 | O26: =Input_Data_Electrified!S6*State_Electricity_Factors!B6 -> 195.7555
A27: Georgia | B27: {=Input_Data_Electrified!$B7:$J7*TRANSPOSE(Impact_Factors!$C$2:$C$10)} -> 68.1378 | C27: 6.27 | D27: 51.221 | E27: 24.2575 | F27: 0.0152789 | G27: 306.495 | H27: 0 | I27: 764.4 | J27: 0 | K27: =Input_Data_Electrified!K7*State_Electricity_Factors!B7 -> 399.46399 | L27: =Input_Data_Electrified!P7*Impact_Factors!$C$11 -> 0 | M27: =Input_Data_Electrified!Q7*Impact_Factors!$C$11 -> 0 | N27: =Input_Data_Electrified!R7*State_Electricity_Factors!B7 -> 95.158 | O27: =Input_Data_Electrified!S7*State_Electricity_Factors!B7 -> 180.9815
A28: Kansas | B28: {=Input_Data_Electrified!$B8:$J8*TRANSPOSE(Impact_Factors!$C$2:$C$10)} -> 95.589 | C28: 14.63 | D28: 35.604 | E28: 12.8619 | F28: 0.0138554 | G28: 304.185 | H28: 0 | I28: 218.4 | J28: 0 | K28: =Input_Data_Electrified!K8*State_Electricity_Factors!B8 -> 626.82043 | L28: =Input_Data_Electrified!P8*Impact_Factors!$C$11 -> 0 | M28: =Input_Data_Electrified!Q8*Impact_Factors!$C$11 -> 0 | N28: =Input_Data_Electrified!R8*State_Electricity_Factors!B8 -> 91.274 | O28: =Input_Data_Electrified!S8*State_Electricity_Factors!B8 -> 173.5945
A29: Louisiana | B29: {=Input_Data_Electrified!$B9:$J9*TRANSPOSE(Impact_Factors!$C$2:$C$10)} -> 93.6282 | C29: 30.514 | D29: 39.284 | E29: 17.2546 | F29: 0.0165126 | G29: 246.33 | H29: 0 | I29: 600.6 | J29: 0 | K29: =Input_Data_Electrified!K9*State_Electricity_Factors!B9 -> 423.4658 | L29: =Input_Data_Electrified!P9*Impact_Factors!$C$11 -> 0 | M29: =Input_Data_Electrified!Q9*Impact_Factors!$C$11 -> 0 | N29: =Input_Data_Electrified!R9*State_Electricity_Factors!B9 -> 112.636 | O29: =Input_Data_Electrified!S9*State_Electricity_Factors!B9 -> 214.223
A30: Mississippi | B30: {=Input_Data_Electrified!$B10:$J10*TRANSPOSE(Impact_Factors!$C$2:$C$10)} -> 80.6379 | C30: 29.26 | D30: 22.977 | E30: 17.732 | F30: 0.0144248 | G30: 306.04 | H30: 0 | I30: 764.4 | J30: 0 | K30: =Input_Data_Electrified!K10*State_Electricity_Factors!B10 -> 332.3604 | L30: =Input_Data_Electrified!P10*Impact_Factors!$C$11 -> 0 | M30: =Input_Data_Electrified!Q10*Impact_Factors!$C$11 -> 0 | N30: =Input_Data_Electrified!R10*State_Electricity_Factors!B10 -> 97.1 | O30: =Input_Data_Electrified!S10*State_Electricity_Factors!B10 -> 184.675
A31: Missouri | B31: {=Input_Data_Electrified!$B11:$J11*TRANSPOSE(Impact_Factors!$C$2:$C$10)} -> 51.7161 | C31: 19.019 | D31: 34.04 | E31: 15.1559 | F31: 0.0214474 | G31: 272.72 | H31: 0 | I31: 682.5 | J31: 0 | K31: =Input_Data_Electrified!K11*State_Electricity_Factors!B11 -> 859.45507 | L31: =Input_Data_Electrified!P11*Impact_Factors!$C$11 -> 0 | M31: =Input_Data_Electrified!Q11*Impact_Factors!$C$11 -> 0 | N31: =Input_Data_Electrified!R11*State_Electricity_Factors!B11 -> 174.78 | O31: =Input_Data_Electrified!S11*State_Electricity_Factors!B11 -> 332.415
A32: New Mexico | B32: {=Input_Data_Electrified!$B12:$J12*TRANSPOSE(Impact_Factors!$C$2:$C$10)} -> 95.589 | C32: 14.63 | D32: 35.604 | E32: 12.8619 | F32: 0.0138554 | G32: 304.185 | H32: 0 | I32: 218.4 | J32: 0 | K32: =Input_Data_Electrified!K12*State_Electricity_Factors!B12 -> 1927.9222 | L32: =Input_Data_Electrified!P12*Impact_Factors!$C$11 -> 0 | M32: =Input_Data_Electrified!Q12*Impact_Factors!$C$11 -> 0 | N32: =Input_Data_Electrified!R12*State_Electricity_Factors!B12 -> 153.418 | O32: =Input_Data_Electrified!S12*State_Electricity_Factors!B12 -> 291.7865
A33: North Carolina | B33: {=Input_Data_Electrified!$B13:$J13*TRANSPOSE(Impact_Factors!$C$2:$C$10)} -> 80.883 | C33: 11.913 | D33: 25.208 | E33: 22.3262 | F33: 0.0140452 | G33: 261.275 | H33: 0 | I33: 655.2 | J33: 0 | K33: =Input_Data_Electrified!K13*State_Electricity_Factors!B13 -> 481.15338 | L33: =Input_Data_Electrified!P13*Impact_Factors!$C$11 -> 0 | M33: =Input_Data_Electrified!Q13*Impact_Factors!$C$11 -> 0 | N33: =Input_Data_Electrified!R13*State_Electricity_Factors!B13 -> 85.448 | O33: =Input_Data_Electrified!S13*State_Electricity_Factors!B13 -> 162.514
... A38: Virginia | B38: {=Input_Data_Electrified!$B18:$J18*TRANSPOSE(Impact_Factors!$C$2:$C$10)} -> 95.589 | C38: 14.63 | D38: 35.604 | E38: 12.8619 | F38: 0.0138554 | G38: 304.185 | H38: 0 | I38: 737.1 | J38: 0 | K38: =Input_Data_Electrified!K18*State_Electricity_Factors!B18 -> 286.71096 | L38: =Input_Data_Electrified!P18*Impact_Factors!$C$11 -> 0 | M38: =Input_Data_Electrified!Q18*Impact_Factors!$C$11 -> 0 | N38: =Input_Data_Electrified!R18*State_Electricity_Factors!B18 -> 75.738 | O38: =Input_Data_Electrified!S18*State_Electricity_Factors!B18 -> 144.0465

Sheet Results_Energy_Breakdown
A1: State | B1: Herbicides (MJ/1000kg lint) | C1: Insecticides (MJ /1000kg lint) | D1: Phosphoric Acid (MJ/1000kg lint) | E1: Potassium Oxide (MJ/1000kg lint) | F1: Calcium Carbonate (MJ/1000kg lint) | G1: N Fertilizer (MJ/1000kg lint) | H1: Diesel (MJ/1000kg lint) | I1: N2O Emission (MJ/1000kg lint) | J1: Irrigation Water (MJ/1000kg lint)_year 2023 surveyed | K1: Electricity (MJ /1000 kg cotton lint) | L1: NG Ginning Low (MJ/1000kg lint) | M1: NG Ginning High (MJ/1000kg lint) | N1: Electricity Ginning Low (MJ/1000kg lint) | O1: Electricity Ginning High (MJ/1000kg lint)
A2: Alabama | B2: {=Input_Data!$B2:$J2*TRANSPOSE(Impact_Factors!$D$2:$D$10)} -> 1252.15 | C2: 85.96 | D2: 677.28 | E2: 549.2239 | F2: 0.1908 | G2: 5226.65 | H2: 1166.2896 | I2: 0 | J2: 0 | K2: =Input_Data!K2*State_Electricity_Factors!C2 -> 2521.1479 | L2: =Input_Data!P2*Impact_Factors!$D$11 -> 129.2 | M2: =Input_Data!Q2*Impact_Factors!$D$11 -> 680.2 | N2: =Input_Data!R2*State_Electricity_Factors!C2 -> 1171.1031 | O2: =Input_Data!S2*State_Electricity_Factors!C2 -> 1340.3035
A3: Arizona | B3: {=Input_Data!$B3:$J3*TRANSPOSE(Impact_Factors!$D$2:$D$10)} -> 568.8 | C3: 55.26 | D3: 170.68 | E3: 7.9143 | F3: 0.0432 | G3: 5595.7 | H3: 3308.5248 | I3: 0 | J3: 0 | K3: =Input_Data!K3*State_Electricity_Factors!C3 -> 6737.5921 | L3: =Input_Data!P3*Impact_Factors!$D$11 -> 129.2 | M3: =Input_Data!Q3*Impact_Factors!$D$11 -> 680.2 | N3: =Input_Data!R3*State_Electricity_Factors!C3 -> 1177.0096 | O3: =Input_Data!S3*State_Electricity_Factors!C3 -> 1347.0634
A4: Arkansas | B4: {=Input_Data!$B4:$J4*TRANSPOSE(Impact_Factors!$D$2:$D$10)} -> 995.4 | C4: 368.4 | D4: 543.66 | E4: 432.5058 | F4: 0.2592 | G4: 5627.05 | H4: 2457.168 | I4: 0 | J4: 0 | K4: =Input_Data!K4*State_Electricity_Factors!C4 -> 3384.8343 | L4: =Input_Data!P4*Impact_Factors!$D$11 -> 129.2 | M4: =Input_Data!Q4*Impact_Factors!$D$11 -> 680.2 | N4: =Input_Data!R4*State_Electricity_Factors!C4 -> 1327.6665 | O4: =Input_Data!S4*State_Electricity_Factors!C4 -> 1519.4871
A5: California | B5: {=Input_Data!$B5:$J5*TRANSPOSE(Impact_Factors!$D$2:$D$10)} -> 501.65 | C5: 144.29 | D5: 71.06 | E5: 60.3911 | F5: 0.1548 | G5: 3616.8 | H5: 3284.2992 | I5: 0 | J5: 0 | K5: =Input_Data!K5*State_Electricity_Factors!C5 -> 2997.9546 | L5: =Input_Data!P5*Impact_Factors!$D$11 -> 129.2 | M5: =Input_Data!Q5*Impact_Factors!$D$11 -> 680.2 | N5: =Input_Data!R5*State_Electricity_Factors!C5 -> 1004.1262 | O5: =Input_Data!S5*State_Electricity_Factors!C5 -> 1149.2018
A6: Florida | B6: {=Input_Data!$B6:$J6*TRANSPOSE(Impact_Factors!$D$2:$D$10)} -> 1540.5 | C6: 214.9 | D6: 526.32 | E6: 295.8237 | F6: 0.1752 | G6: 4780.05 | H6: 3813.8016 | I6: 0 | J6: 0 | K6: =Input_Data!K6*State_Electricity_Factors!C6 -> 3268.3741 | L6: =Input_Data!P6*Impact_Factors!$D$11 -> 129.2 | M6: =Input_Data!Q6*Impact_Factors!$D$11 -> 680.2 | N6: =Input_Data!R6*State_Electricity_Factors!C6 -> 1357.56 | O6: =Input_Data!S6*State_Electricity_Factors!C6 -> 1553.6996
A7: Georgia | B7: {=Input_Data!$B7:$J7*TRANSPOSE(Impact_Factors!$D$2:$D$10)} -> 1098.1 | C7: 92.1 | D7: 757.18 | E7: 557.9225 | F7: 0.1932 | G7: 4816.35 | H7: 1951.8912 | I7: 0 | J7: 0 | K7: =Input_Data!K7*State_Electricity_Factors!C7 -> 4789.0701 | L7: =Input_Data!P7*Impact_Factors!$D$11 -> 129.2 | M7: =Input_Data!Q7*Impact_Factors!$D$11 -> 680.2 | N7: =Input_Data!R7*State_Electricity_Factors!C7 -> 1242.8475 | O7: =Input_Data!S7*State_Electricity_Factors!C7 -> 1422.4135
A8: Kansas | B8: {=Input_Data!$B8:$J8*TRANSPOSE(Impact_Factors!$D$2:$D$10)} -> 1540.5 | C8: 214.9 | D8: 526.32 | E8: 295.8237 | F8: 0.1752 | G8: 4780.05 | H8: 3505.7904 | I8: 0 | J8: 0 | K8: =Input_Data!K8*State_Electricity_Factors!C8 -> 6916.0331 | L8: =Input_Data!P8*Impact_Factors!$D$11 -> 129.2 | M8: =Input_Data!Q8*Impact_Factors!$D$11 -> 680.2 | N8: =Input_Data!R8*State_Electricity_Factors!C8 -> 1134.3189 | O8: =Input_Data!S8*State_Electricity_Factors!C8 -> 1298.2047
A9: Louisiana | B9: {=Input_Data!$B9:$J9*TRANSPOSE(Impact_Factors!$D$2:$D$10)} -> 1508.9 | C9: 448.22 | D9: 580.72 | E9: 396.8558 | F9: 0.2088 | G9: 3870.9 | H9: 2851.6992 | I9: 0 | J9: 0 | K9: =Input_Data!K9*State_Electricity_Factors!C9 -> 3972.1834 | L9: =Input_Data!P9*Impact_Factors!$D$11 -> 129.2 | M9: =Input_Data!Q9*Impact_Factors!$D$11 -> 680.2 | N9: =Input_Data!R9*State_Electricity_Factors!C9 -> 1459.5355 | O9: =Input_Data!S9*State_Electricity_Factors!C9 -> 1670.4084
A10: Mississippi | B10: {=Input_Data!$B10:$J10*TRANSPOSE(Impact_Factors!$D$2:$D$10)} -> 1299.55 | C10: 429.8 | D10: 339.66 | E10: 407.836 | F10: 0.1824 | G10: 4809.2 | H10: 2682.12 | I10: 0 | J10: 0 | K10: =Input_Data!K10*State_Electricity_Factors!C10 -> 3218.8416 | L10: =Input_Data!P10*Impact_Factors!$D$11 -> 129.2 | M10: =Input_Data!Q10*Impact_Factors!$D$11 -> 680.2 | N10: =Input_Data!R10*State_Electricity_Factors!C10 -> 1329.5217 | O10: =Input_Data!S10*State_Electricity_Factors!C10 -> 1521.6103
A11: Missouri | B11: {=Input_Data!$B11:$J11*TRANSPOSE(Impact_Factors!$D$2:$D$10)} -> 833.45 | C11: 279.37 | D11: 503.2 | E11: 348.5857 | F11: 0.2712 | G11: 4285.6 | H11: 3246.2304 | I11: 0 | J11: 0 | K11: =Input_Data!K11*State_Electricity_Factors!C11 -> 6067.4079 | L11: =Input_Data!P11*Impact_Factors!$D$11 -> 129.2 | M11: =Input_Data!Q11*Impact_Factors!$D$11 -> 680.2 | N11: =Input_Data!R11*State_Electricity_Factors!C11 -> 1564.0477 | O11: =Input_Data!S11*State_Electricity_Factors!C11 -> 1790.0206
A12: New Mexico | B12: {=Input_Data!$B12:$J12*TRANSPOSE(Impact_Factors!$D$2:$D$10)} -> 1540.5 | C12: 214.9 | D12: 526.32 | E12: 295.8237 | F12: 0.1752 | G12: 4780.05 | H12: 6918.1392 | I12: 0 | J12: 0 | K12: =Input_Data!K12*State_Electricity_Factors!C12 -> 16505.416 | L12: =Input_Data!P12*Impact_Factors!$D$11 -> 129.2 | M12: =Input_Data!Q12*Impact_Factors!$D$11 -> 680.2 | N12: =Input_Data!R12*State_Electricity_Factors!C12 -> 1524.8494 | O12: =Input_Data!S12*State_Electricity_Factors!C12 -> 1745.1589
A13: North Carolina | B13: {=Input_Data!$B13:$J13*TRANSPOSE(Impact_Factors!$D$2:$D$10)} -> 1303.5 | C13: 174.99 | D13: 372.64 | E13: 513.5026 | F13: 0.1776 | G13: 4105.75 | H13: 2612.904 | I13: 0 | J13: 0 | K13: =Input_Data!K13*State_Electricity_Factors!C13 -> 5962.4049 | L13: =Input_Data!P13*Impact_Factors!$D$11 -> 129.2 | M13: =Input_Data!Q13*Impact_Factors!$D$11 -> 680.2 | N13: =Input_Data!R13*State_Electricity_Factors!C13 -> 1152.7738 | O13: =Input_Data!S13*State_Electricity_Factors!C13 -> 1319.326
... A18: Virginia | B18: {=Input_Data!$B18:$J18*TRANSPOSE(Impact_Factors!$D$2:$D$10)} -> 1540.5 | C18: 214.9 | D18: 526.32 | E18: 295.8237 | F18: 0.1752 | G18: 4780.05 | H18: 1685.4096 | I18: 0 | J18: 0 | K18: =Input_Data!K18*State_Electricity_Factors!C18 -> 4142.7892 | L18: =Input_Data!P18*Impact_Factors!$D$11 -> 129.2 | M18: =Input_Data!Q18*Impact_Factors!$D$11 -> 680.2 | N18: =Input_Data!R18*State_Electricity_Factors!C18 -> 1175.5179 | O18: =Input_Data!S18*State_Electricity_Factors!C18 -> 1345.3562
A20: pro-electricity
A21: State | B21: Herbicides (MJ/1000kg lint) | C21: Insecticides (MJ /1000kg lint) | D21: Phosphoric Acid (MJ/1000kg lint) | E21: Potassium Oxide (MJ/1000kg lint) | F21: Calcium Carbonate (MJ/1000kg lint) | G21: N Fertilizer (MJ/1000kg lint) | H21: Diesel (MJ/1000kg lint) | I21: N2O Emission (MJ/1000kg lint) | J21: Irrigation Water (MJ/1000kg lint)_year 2023 surveyed | K21: Electricity (MJ /1000 kg cotton lint) | L21: NG Ginning Low (MJ/1000kg lint) | M21: NG Ginning High (MJ/1000kg lint) | N21: Electricity Ginning Low (MJ/1000kg lint) | O21: Electricity Ginning High (MJ/1000kg lint)
A22: Alabama | B22: {=Input_Data_Electrified!$B2:$J2*TRANSPOSE(Impact_Factors!$D$2:$D$10)} -> 1252.15 | C22: 85.96 | D22: 677.28 | E22: 549.2239 | F22: 0.1908 | G22: 5226.65 | H22: 0 | I22: 0 | J22: 0 | K22: =Input_Data_Electrified!K2*State_Electricity_Factors!C2 -> 3423.9149 | L22: =Input_Data_Electrified!P2*Impact_Factors!$D$11 -> 0 | M22: =Input_Data_Electrified!Q2*Impact_Factors!$D$11 -> 0 | N22: =Input_Data_Electrified!R2*State_Electricity_Factors!C2 -> 1434.8784 | O22: =Input_Data_Electrified!S2*State_Electricity_Factors!C2 -> 2729.0028
A23: Arizona | B23: {=Input_Data_Electrified!$B3:$J3*TRANSPOSE(Impact_Factors!$D$2:$D$10)} -> 568.8 | C23: 55.26 | D23: 170.68 | E23: 7.9143 | F23: 0.0432 | G23: 5595.7 | H23: 0 | I23: 0 | J23: 0 | K23: =Input_Data_Electrified!K3*State_Electricity_Factors!C3 -> 9311.4734 | L23: =Input_Data_Electrified!P3*Impact_Factors!$D$11 -> 0 | M23: =Input_Data_Electrified!Q3*Impact_Factors!$D$11 -> 0 | N23: =Input_Data_Electrified!R3*State_Electricity_Factors!C3 -> 1442.1152 | O23: =Input_Data_Electrified!S3*State_Electricity_Factors!C3 -> 2742.7665
A24: Arkansas | B24: {=Input_Data_Electrified!$B4:$J4*TRANSPOSE(Impact_Factors!$D$2:$D$10)} -> 995.4 | C24: 368.4 | D24: 543.66 | E24: 432.5058 | F24: 0.2592 | G24: 5627.05 | H24: 0 | I24: 0 | J24: 0 | K24: =Input_Data_Electrified!K4*State_Electricity_Factors!C4 -> 5541.0787 | L24: =Input_Data_Electrified!P4*Impact_Factors!$D$11 -> 0 | M24: =Input_Data_Electrified!Q4*Impact_Factors!$D$11 -> 0 | N24: =Input_Data_Electrified!R4*State_Electricity_Factors!C4 -> 1626.7056 | O24: =Input_Data_Electrified!S4*State_Electricity_Factors!C4 -> 3093.84
A25: California | B25: {=Input_Data_Electrified!$B5:$J5*TRANSPOSE(Impact_Factors!$D$2:$D$10)} -> 501.65 | C25: 144.29 | D25: 71.06 | E25: 60.3911 | F25: 0.1548 | G25: 3616.8 | H25: 0 | I25: 0 | J25: 0 | K25: =Input_Data_Electrified!K5*State_Electricity_Factors!C5 -> 5177.6968 | L25: =Input_Data_Electrified!P5*Impact_Factors!$D$11 -> 0 | M25: =Input_Data_Electrified!Q5*Impact_Factors!$D$11 -> 0 | N25: =Input_Data_Electrified!R5*State_Electricity_Factors!C5 -> 1230.2921 | O25: =Input_Data_Electrified!S5*State_Electricity_Factors!C5 -> 2339.8991
A26: Florida | B26: {=Input_Data_Electrified!$B6:$J6*TRANSPOSE(Impact_Factors!$D$2:$D$10)} -> 1540.5 | C26: 214.9 | D26: 526.32 | E26: 295.8237 | F26: 0.1752 | G26: 4780.05 | H26: 0 | I26: 0 | J26: 0 | K26: =Input_Data_Electrified!K6*State_Electricity_Factors!C6 -> 6690.4628 | L26: =Input_Data_Electrified!P6*Impact_Factors!$D$11 -> 0 | M26: =Input_Data_Electrified!Q6*Impact_Factors!$D$11 -> 0 | N26: =Input_Data_Electrified!R6*State_Electricity_Factors!C6 -> 1663.3322 | O26: =Input_Data_Electrified!S6*State_Electricity_Factors!C6 -> 3163.5003
A27: Georgia | B27: {=Input_Data_Electrified!$B7:$J7*TRANSPOSE(Impact_Factors!$D$2:$D$10)} -> 1098.1 | C27: 92.1 | D27: 757.18 | E27: 557.9225 | F27: 0.1932 | G27: 4816.35 | H27: 0 | I27: 0 | J27: 0 | K27: =Input_Data_Electrified!K7*State_Electricity_Factors!C7 -> 6392.4911 | L27: =Input_Data_Electrified!P7*Impact_Factors!$D$11 -> 0 | M27: =Input_Data_Electrified!Q7*Impact_Factors!$D$11 -> 0 | N27: =Input_Data_Electrified!R7*State_Electricity_Factors!C7 -> 1522.7822 | O27: =Input_Data_Electrified!S7*State_Electricity_Factors!C7 -> 2896.1875
A28: Kansas | B28: {=Input_Data_Electrified!$B8:$J8*TRANSPOSE(Impact_Factors!$D$2:$D$10)} -> 1540.5 | C28: 214.9 | D28: 526.32 | E28: 295.8237 | F28: 0.1752 | G28: 4780.05 | H28: 0 | I28: 0 | J28: 0 | K28: =Input_Data_Electrified!K8*State_Electricity_Factors!C8 -> 9544.4559 | L28: =Input_Data_Electrified!P8*Impact_Factors!$D$11 -> 0 | M28: =Input_Data_Electrified!Q8*Impact_Factors!$D$11 -> 0 | N28: =Input_Data_Electrified!R8*State_Electricity_Factors!C8 -> 1389.809 | O28: =Input_Data_Electrified!S8*State_Electricity_Factors!C8 -> 2643.285
A29: Louisiana | B29: {=Input_Data_Electrified!$B9:$J9*TRANSPOSE(Impact_Factors!$D$2:$D$10)} -> 1508.9 | C29: 448.22 | D29: 580.72 | E29: 396.8558 | F29: 0.2088 | G29: 3870.9 | H29: 0 | I29: 0 | J29: 0 | K29: =Input_Data_Electrified!K9*State_Electricity_Factors!C9 -> 6723.1955 | L29: =Input_Data_Electrified!P9*Impact_Factors!$D$11 -> 0 | M29: =Input_Data_Electrified!Q9*Impact_Factors!$D$11 -> 0 | N29: =Input_Data_Electrified!R9*State_Electricity_Factors!C9 -> 1788.2763 | O29: =Input_Data_Electrified!S9*State_Electricity_Factors!C9 -> 3401.1321
A30: Mississippi | B30: {=Input_Data_Electrified!$B10:$J10*TRANSPOSE(Impact_Factors!$D$2:$D$10)} -> 1299.55 | C30: 429.8 | D30: 339.66 | E30: 407.836 | F30: 0.1824 | G30: 4809.2 | H30: 0 | I30: 0 | J30: 0 | K30: =Input_Data_Electrified!K10*State_Electricity_Factors!C10 -> 5575.7773 | L30: =Input_Data_Electrified!P10*Impact_Factors!$D$11 -> 0 | M30: =Input_Data_Electrified!Q10*Impact_Factors!$D$11 -> 0 | N30: =Input_Data_Electrified!R10*State_Electricity_Factors!C10 -> 1628.9786 | O30: =Input_Data_Electrified!S10*State_Electricity_Factors!C10 -> 3098.1629
A31: Missouri | B31: {=Input_Data_Electrified!$B11:$J11*TRANSPOSE(Impact_Factors!$D$2:$D$10)} -> 833.45 | C31: 279.37 | D31: 503.2 | E31: 348.5857 | F31: 0.2712 | G31: 4285.6 | H31: 0 | I31: 0 | J31: 0 | K31: =Input_Data_Electrified!K11*State_Electricity_Factors!C11 -> 9423.265 | L31: =Input_Data_Electrified!P11*Impact_Factors!$D$11 -> 0 | M31: =Input_Data_Electrified!Q11*Impact_Factors!$D$11 -> 0 | N31: =Input_Data_Electrified!R11*State_Electricity_Factors!C11 -> 1916.3285 | O31: =Input_Data_Electrified!S11*State_Electricity_Factors!C11 -> 3644.6752
A32: New Mexico | B32: {=Input_Data_Electrified!$B12:$J12*TRANSPOSE(Impact_Factors!$D$2:$D$10)} -> 1540.5 | C32: 214.9 | D32: 526.32 | E32: 295.8237 | F32: 0.1752 | G32: 4780.05 | H32: 0 | I32: 0 | J32: 0 | K32: =Input_Data_Electrified!K12*State_Electricity_Factors!C12 -> 23477.946 | L32: =Input_Data_Electrified!P12*Impact_Factors!$D$11 -> 0 | M32: =Input_Data_Electrified!Q12*Impact_Factors!$D$11 -> 0 | N32: =Input_Data_Electrified!R12*State_Electricity_Factors!C12 -> 1868.3013 | O32: =Input_Data_Electrified!S12*State_Electricity_Factors!C12 -> 3553.332
A33: North Carolina | B33: {=Input_Data_Electrified!$B13:$J13*TRANSPOSE(Impact_Factors!$D$2:$D$10)} -> 1303.5 | C33: 174.99 | D33: 372.64 | E33: 513.5026 | F33: 0.1776 | G33: 4105.75 | H33: 0 | I33: 0 | J33: 0 | K33: =Input_Data_Electrified!K13*State_Electricity_Factors!C13 -> 7953.2692 | L33: =Input_Data_Electrified!P13*Impact_Factors!$D$11 -> 0 | M33: =Input_Data_Electrified!Q13*Impact_Factors!$D$11 -> 0 | N33: =Input_Data_Electrified!R13*State_Electricity_Factors!C13 -> 1412.4206 | O33: =Input_Data_Electrified!S13*State_Electricity_Factors!C13 -> 2686.2902
... A38: Virginia | B38: {=Input_Data_Electrified!$B18:$J18*TRANSPOSE(Impact_Factors!$D$2:$D$10)} -> 1540.5 | C38: 214.9 | D38: 526.32 | E38: 295.8237 | F38: 0.1752 | G38: 4780.05 | H38: 0 | I38: 0 | J38: 0 | K38: =Input_Data_Electrified!K18*State_Electricity_Factors!C18 -> 5452.2993 | L38: =Input_Data_Electrified!P18*Impact_Factors!$D$11 -> 0 | M38: =Input_Data_Electrified!Q18*Impact_Factors!$D$11 -> 0 | N38: =Input_Data_Electrified!R18*State_Electricity_Factors!C18 -> 1440.2876 | O38: =Input_Data_Electrified!S18*State_Electricity_Factors!C18 -> 2739.2905

Sheet Results_Water_Breakdown
A1: State | B1: Herbicides (L/1000kg lint) | C1: Insecticides (L/1000kg lint) | D1: Phosphoric Acid (L/1000kg lint) | E1: Potassium Oxide (L/1000kg lint) | F1: Calcium Carbonate (L/1000kg lint) | G1: N Fertilizer (L/1000kg lint) | H1: Diesel (L/1000kg lint) | I1: N2O Emission (L/1000kg lint) | J1: Irrigation Water (L/1000kg lint)_year 2023 surveyed | K1: Electricity (L /1000 kg cotton lint) | L1: NG Ginning Low (L/1000kg lint) | M1: NG Ginning High (L/1000kg lint) | N1: Electricity Ginning Low (L/1000kg lint) | O1: Electricity Ginning High (L/1000kg lint)
A2: Alabama | B2: {=Input_Data!$B2:$J2*TRANSPOSE(Impact_Factors!$E$2:$E$10)} -> 214.7358 | C2: 10.8948 | D2: 1466.5104 | E2: 761.8267 | F2: 0.1749 | G2: 1458.7105 | H2: 83.3064 | I2: 0 | J2: 111785.91 | K2: =Input_Data!K2*State_Electricity_Factors!D2 -> 834.40369 | L2: =Input_Data!P2*Impact_Factors!$E$11 -> 1.41032 | M2: =Input_Data!Q2*Impact_Factors!$E$11 -> 7.42492 | N2: =Input_Data!R2*State_Electricity_Factors!D2 -> 387.59043 | O2: =Input_Data!S2*State_Electricity_Factors!D2 -> 443.58929
A3: Arizona | B3: {=Input_Data!$B3:$J3*TRANSPOSE(Impact_Factors!$E$2:$E$10)} -> 97.5456 | C3: 7.0038 | D3: 369.5724 | E3: 10.9779 | F3: 0.0396 | G3: 1561.709 | H3: 236.3232 | I3: 0 | J3: 7132124.4 | K3: =Input_Data!K3*State_Electricity_Factors!D3 -> 2223.2423 | L3: =Input_Data!P3*Impact_Factors!$E$11 -> 1.41032 | M3: =Input_Data!Q3*Impact_Factors!$E$11 -> 7.42492 | N3: =Input_Data!R3*State_Electricity_Factors!D3 -> 388.38467 | O3: =Input_Data!S3*State_Electricity_Factors!D3 -> 444.49829
A4: Arkansas | B4: {=Input_Data!$B4:$J4*TRANSPOSE(Impact_Factors!$E$2:$E$10)} -> 170.7048 | C4: 46.692 | D4: 1177.1838 | E4: 599.9274 | F4: 0.2376 | G4: 1570.4585 | H4: 175.512 | I4: 0 | J4: 1435741.7 | K4: =Input_Data!K4*State_Electricity_Factors!D4 -> 906.35743 | L4: =Input_Data!P4*Impact_Factors!$E$11 -> 1.41032 | M4: =Input_Data!Q4*Impact_Factors!$E$11 -> 7.42492 | N4: =Input_Data!R4*State_Electricity_Factors!D4 -> 355.5094 | O4: =Input_Data!S4*State_Electricity_Factors!D4 -> 406.87322
A5: California | B5: {=Input_Data!$B5:$J5*TRANSPOSE(Impact_Factors!$E$2:$E$10)} -> 86.0298 | C5: 18.2877 | D5: 153.8658 | E5: 83.7683 | F5: 0.1419 | G5: 1009.416 | H5: 234.5928 | I5: 0 | J5: 5342918 | K5: =Input_Data!K5*State_Electricity_Factors!D5 -> 2120.0193 | L5: =Input_Data!P5*Impact_Factors!$E$11 -> 1.41032 | M5: =Input_Data!Q5*Impact_Factors!$E$11 -> 7.42492 | N5: =Input_Data!R5*State_Electricity_Factors!D5 -> 710.07308 | O5: =Input_Data!S5*State_Electricity_Factors!D5 -> 812.66408
A6: Florida | B6: {=Input_Data!$B6:$J6*TRANSPOSE(Impact_Factors!$E$2:$E$10)} -> 264.186 | C6: 27.237 | D6: 1139.6376 | E6: 410.3361 | F6: 0.1606 | G6: 1334.0685 | H6: 272.4144 | I6: 0 | J6: 344354.88 | K6: =Input_Data!K6*State_Electricity_Factors!D6 -> 410.17689 | L6: =Input_Data!P6*Impact_Factors!$E$11 -> 1.41032 | M6: =Input_Data!Q6*Impact_Factors!$E$11 -> 7.42492 | N6: =Input_Data!R6*State_Electricity_Factors!D6 -> 170.37209 | O6: =Input_Data!S6*State_Electricity_Factors!D6 -> 194.98737
A7: Georgia | B7: {=Input_Data!$B7:$J7*TRANSPOSE(Impact_Factors!$E$2:$E$10)} -> 188.3172 | C7: 11.673 | D7: 1639.5174 | E7: 773.8925 | F7: 0.1771 | G7: 1344.1995 | H7: 139.4208 | I7: 0 | J7: 446116.14 | K7: =Input_Data!K7*State_Electricity_Factors!D7 -> 982.62552 | L7: =Input_Data!P7*Impact_Factors!$E$11 -> 1.41032 | M7: =Input_Data!Q7*Impact_Factors!$E$11 -> 7.42492 | N7: =Input_Data!R7*State_Electricity_Factors!D7 -> 255.00851 | O7: =Input_Data!S7*State_Electricity_Factors!D7 -> 291.85202
A8: Kansas | B8: {=Input_Data!$B8:$J8*TRANSPOSE(Impact_Factors!$E$2:$E$10)} -> 264.186 | C8: 27.237 | D8: 1139.6376 | E8: 410.3361 | F8: 0.1606 | G8: 1334.0685 | H8: 250.4136 | I8: 0 | J8: 480094.56 | K8: =Input_Data!K8*State_Electricity_Factors!D8 -> 1056.1956 | L8: =Input_Data!P8*Impact_Factors!$E$11 -> 1.41032 | M8: =Input_Data!Q8*Impact_Factors!$E$11 -> 7.42492 | N8: =Input_Data!R8*State_Electricity_Factors!D8 -> 173.22975 | O8: =Input_Data!S8*State_Electricity_Factors!D8 -> 198.25789
A9: Louisiana | B9: {=Input_Data!$B9:$J9*TRANSPOSE(Impact_Factors!$E$2:$E$10)} -> 258.7668 | C9: 56.8086 | D9: 1257.4296 | E9: 550.4774 | F9: 0.1914 | G9: 1080.333 | H9: 203.6928 | I9: 0 | J9: 444194.66 | K9: =Input_Data!K9*State_Electricity_Factors!D9 -> 567.35751 | L9: =Input_Data!P9*Impact_Factors!$E$11 -> 1.41032 | M9: =Input_Data!Q9*Impact_Factors!$E$11 -> 7.42492 | N9: =Input_Data!R9*State_Electricity_Factors!D9 -> 208.46933 | O9: =Input_Data!S9*State_Electricity_Factors!D9 -> 238.58888
A10: Mississippi | B10: {=Input_Data!$B10:$J10*TRANSPOSE(Impact_Factors!$E$2:$E$10)} -> 222.8646 | C10: 54.474 | D10: 735.4638 | E10: 565.708 | F10: 0.1672 | G10: 1342.204 | H10: 191.58 | I10: 0 | J10: 463419.46 | K10: =Input_Data!K10*State_Electricity_Factors!D10 -> 377.16853 | L10: =Input_Data!P10*Impact_Factors!$E$11 -> 1.41032 | M10: =Input_Data!Q10*Impact_Factors!$E$11 -> 7.42492 | N10: =Input_Data!R10*State_Electricity_Factors!D10 -> 155.78702 | O10: =Input_Data!S10*State_Electricity_Factors!D10 -> 178.29505
A11: Missouri | B11: {=Input_Data!$B11:$J11*TRANSPOSE(Impact_Factors!$E$2:$E$10)} -> 142.9314 | C11: 35.4081 | D11: 1089.576 | E11: 483.5221 | F11: 0.2486 | G11: 1196.072 | H11: 231.8736 | I11: 0 | J11: 651568.59 | K11: =Input_Data!K11*State_Electricity_Factors!D11 -> 1174.7328 | L11: =Input_Data!P11*Impact_Factors!$E$11 -> 1.41032 | M11: =Input_Data!Q11*Impact_Factors!$E$11 -> 7.42492 | N11: =Input_Data!R11*State_Electricity_Factors!D11 -> 302.82095 | O11: =Input_Data!S11*State_Electricity_Factors!D11 -> 346.57237
A12: New Mexico | B12: {=Input_Data!$B12:$J12*TRANSPOSE(Impact_Factors!$E$2:$E$10)} -> 264.186 | C12: 27.237 | D12: 1139.6376 | E12: 410.3361 | F12: 0.1606 | G12: 1334.0685 | H12: 494.1528 | I12: 0 | J12: 3962167.3 | K12: =Input_Data!K12*State_Electricity_Factors!D12 -> 2261.0311 | L12: =Input_Data!P12*Impact_Factors!$E$11 -> 1.41032 | M12: =Input_Data!Q12*Impact_Factors!$E$11 -> 7.42492 | N12: =Input_Data!R12*State_Electricity_Factors!D12 -> 208.88488 | O12: =Input_Data!S12*State_Electricity_Factors!D12 -> 239.06446
A13: North Carolina | B13: {=Input_Data!$B13:$J13*TRANSPOSE(Impact_Factors!$E$2:$E$10)} -> 223.542 | C13: 22.1787 | D13: 806.8752 | E13: 712.2778 | F13: 0.1628 | G13: 1145.8775 | H13: 186.636 | I13: 0 | J13: 28744.973 | K13: =Input_Data!K13*State_Electricity_Factors!D13 -> 1513.5419 | L13: =Input_Data!P13*Impact_Factors!$E$11 -> 1.41032 | M13: =Input_Data!Q13*Impact_Factors!$E$11 -> 7.42492 | N13: =Input_Data!R13*State_Electricity_Factors!D13 -> 292.6288 | O13: =Input_Data!S13*State_Electricity_Factors!D13 -> 334.90766
... A18: Virginia | B18: {=Input_Data!$B18:$J18*TRANSPOSE(Impact_Factors!$E$2:$E$10)} -> 264.186 | C18: 27.237 | D18: 1139.6376 | E18: 410.3361 | F18: 0.1606 | G18: 1334.0685 | H18: 120.3864 | I18: 0 | J18: 1703.3495 | K18: =Input_Data!K18*State_Electricity_Factors!D18 -> 804.35294 | L18: =Input_Data!P18*Impact_Factors!$E$11 -> 1.41032 | M18: =Input_Data!Q18*Impact_Factors!$E$11 -> 7.42492 | N18: =Input_Data!R18*State_Electricity_Factors!D18 -> 228.23544 | O18: =Input_Data!S18*State_Electricity_Factors!D18 -> 261.21078
A20: pro-electricity
A21: State | B21: Herbicides (L/1000kg lint) | C21: Insecticides (L/1000kg lint) | D21: Phosphoric Acid (L/1000kg lint) | E21: Potassium Oxide (L/1000kg lint) | F21: Calcium Carbonate (L/1000kg lint) | G21: N Fertilizer (L/1000kg lint) | H21: Diesel (L/1000kg lint) | I21: N2O Emission (L/1000kg lint) | J21: Irrigation Water (L/1000kg lint)_year 2023 surveyed | K21: Electricity (L /1000 kg cotton lint) | L21: NG Ginning Low (L/1000kg lint) | M21: NG Ginning High (L/1000kg lint) | N21: Electricity Ginning Low (L/1000kg lint) | O21: Electricity Ginning High (L/1000kg lint)
A22: Alabama | B22: {=Input_Data_Electrified!$B2:$J2*TRANSPOSE(Impact_Factors!$E$2:$E$10)} -> 214.7358 | C22: 10.8948 | D22: 1466.5104 | E22: 761.8267 | F22: 0.1749 | G22: 1458.7105 | H22: 0 | I22: 0 | J22: 111785.91 | K22: =Input_Data_Electrified!K2*State_Electricity_Factors!D2 -> 1133.1851 | L22: =Input_Data_Electrified!P2*Impact_Factors!$E$11 -> 0 | M22: =Input_Data_Electrified!Q2*Impact_Factors!$E$11 -> 0 | N22: =Input_Data_Electrified!R2*State_Electricity_Factors!D2 -> 474.88997 | O22: =Input_Data_Electrified!S2*State_Electricity_Factors!D2 -> 903.19573
A23: Arizona | B23: {=Input_Data_Electrified!$B3:$J3*TRANSPOSE(Impact_Factors!$E$2:$E$10)} -> 97.5456 | C23: 7.0038 | D23: 369.5724 | E23: 10.9779 | F23: 0.0396 | G23: 1561.709 | H23: 0 | I23: 0 | J23: 7132124.4 | K23: =Input_Data_Electrified!K3*State_Electricity_Factors!D3 -> 3072.5608 | L23: =Input_Data_Electrified!P3*Impact_Factors!$E$11 -> 0 | M23: =Input_Data_Electrified!Q3*Impact_Factors!$E$11 -> 0 | N23: =Input_Data_Electrified!R3*State_Electricity_Factors!D3 -> 475.86311 | O23: =Input_Data_Electrified!S3*State_Electricity_Factors!D3 -> 905.04655
A24: Arkansas | B24: {=Input_Data_Electrified!$B4:$J4*TRANSPOSE(Impact_Factors!$E$2:$E$10)} -> 170.7048 | C24: 46.692 | D24: 1177.1838 | E24: 599.9274 | F24: 0.2376 | G24: 1570.4585 | H24: 0 | I24: 0 | J24: 1435741.7 | K24: =Input_Data_Electrified!K4*State_Electricity_Factors!D4 -> 1483.7352 | L24: =Input_Data_Electrified!P4*Impact_Factors!$E$11 -> 0 | M24: =Input_Data_Electrified!Q4*Impact_Factors!$E$11 -> 0 | N24: =Input_Data_Electrified!R4*State_Electricity_Factors!D4 -> 435.58313 | O24: =Input_Data_Electrified!S4*State_Electricity_Factors!D4 -> 828.43784
A25: California | B25: {=Input_Data_Electrified!$B5:$J5*TRANSPOSE(Impact_Factors!$E$2:$E$10)} -> 86.0298 | C25: 18.2877 | D25: 153.8658 | E25: 83.7683 | F25: 0.1419 | G25: 1009.416 | H25: 0 | I25: 0 | J25: 5342918 | K25: =Input_Data_Electrified!K5*State_Electricity_Factors!D5 -> 3661.4353 | L25: =Input_Data_Electrified!P5*Impact_Factors!$E$11 -> 0 | M25: =Input_Data_Electrified!Q5*Impact_Factors!$E$11 -> 0 | N25: =Input_Data_Electrified!R5*State_Electricity_Factors!D5 -> 870.00752 | O25: =Input_Data_Electrified!S5*State_Electricity_Factors!D5 -> 1654.6719
A26: Florida | B26: {=Input_Data_Electrified!$B6:$J6*TRANSPOSE(Impact_Factors!$E$2:$E$10)} -> 264.186 | C26: 27.237 | D26: 1139.6376 | E26: 410.3361 | F26: 0.1606 | G26: 1334.0685 | H26: 0 | I26: 0 | J26: 344354.88 | K26: =Input_Data_Electrified!K6*State_Electricity_Factors!D6 -> 839.64476 | L26: =Input_Data_Electrified!P6*Impact_Factors!$E$11 -> 0 | M26: =Input_Data_Electrified!Q6*Impact_Factors!$E$11 -> 0 | N26: =Input_Data_Electrified!R6*State_Electricity_Factors!D6 -> 208.74612 | O26: =Input_Data_Electrified!S6*State_Electricity_Factors!D6 -> 397.01535
A27: Georgia | B27: {=Input_Data_Electrified!$B7:$J7*TRANSPOSE(Impact_Factors!$E$2:$E$10)} -> 188.3172 | C27: 11.673 | D27: 1639.5174 | E27: 773.8925 | F27: 0.1771 | G27: 1344.1995 | H27: 0 | I27: 0 | J27: 446116.14 | K27: =Input_Data_Electrified!K7*State_Electricity_Factors!D7 -> 1311.6168 | L27: =Input_Data_Electrified!P7*Impact_Factors!$E$11 -> 0 | M27: =Input_Data_Electrified!Q7*Impact_Factors!$E$11 -> 0 | N27: =Input_Data_Electrified!R7*State_Electricity_Factors!D7 -> 312.44576 | O27: =Input_Data_Electrified!S7*State_Electricity_Factors!D7 -> 594.24224
A28: Kansas | B28: {=Input_Data_Electrified!$B8:$J8*TRANSPOSE(Impact_Factors!$E$2:$E$10)} -> 264.186 | C28: 27.237 | D28: 1139.6376 | E28: 410.3361 | F28: 0.1606 | G28: 1334.0685 | H28: 0 | I28: 0 | J28: 480094.56 | K28: =Input_Data_Electrified!K8*State_Electricity_Factors!D8 -> 1457.6004 | L28: =Input_Data_Electrified!P8*Impact_Factors!$E$11 -> 0 | M28: =Input_Data_Electrified!Q8*Impact_Factors!$E$11 -> 0 | N28: =Input_Data_Electrified!R8*State_Electricity_Factors!D8 -> 212.24742 | O28: =Input_Data_Electrified!S8*State_Electricity_Factors!D8 -> 403.67449
